2023-06-25 10:28:23,213 ERROR [C:\Code\Python\Django\Udemy_django\ClassBasedView\class_based_view\class_based_view\middleware.py:16] この名前は仕様できません
Traceback (most recent call last):
  File "D:\Code\Anaconda\lib\site-packages\django\core\handlers\base.py", line 197, in _get_response
    response = wrapped_callback(request, *callback_args, **callback_kwargs)
  File "D:\Code\Anaconda\lib\site-packages\django\views\generic\base.py", line 103, in view
    return self.dispatch(request, *args, **kwargs)
  File "D:\Code\Anaconda\lib\site-packages\django\views\generic\base.py", line 142, in dispatch
    return handler(request, *args, **kwargs)
  File "D:\Code\Anaconda\lib\site-packages\django\views\generic\base.py", line 216, in get
    context = self.get_context_data(**kwargs)
  File "C:\Code\Python\Django\Udemy_django\ClassBasedView\class_based_view\store\views.py", line 52, in get_context_data
    raise Http404("この名前は仕様できません")
django.http.response.Http404: この名前は仕様できません
